<?xml version="1.0" encoding="utf-8"?>
<robot xmlns:xacro="http://www.ros.org/wiki/xacro" name="towing_core">
  <xacro:arg name="mesh_path" default="towing/meshes" />
  <xacro:property name="mesh_path" value="$(arg mesh_path)" />
  <!-- =================== -->
  <!--      BASE ROBOT     -->
  <!-- =================== -->
  <link name="base_link">
    <inertial>
      <origin
        xyz="0.11735 -8.1935E-05 -0.30584"
        rpy="0 0 0" />
      <mass value="50" />
      <inertia
        ixx="56.116"
        ixy="-0.74787"
        ixz="7.1158"
        iyy="93.562"
        iyz="0.080093"
        izz="132.22" />
    </inertial>
    <visual>
      <origin
        xyz="0 0 0"
        rpy="0 0 0" />
      <geometry>
        <mesh
          filename="file://${mesh_path}/base_link.STL" />
      </geometry>
      <material
        name="">
        <color
          rgba="0.21961 0.44314 1 1" />
      </material>
    </visual>
    <collision>
      <origin
        xyz="0 0 0"
        rpy="0 0 0" />
      <geometry>
        <mesh
          filename="file://${mesh_path}/base_link.STL" />
      </geometry>
    </collision>
  </link>

  <!-- =================== -->
  <!-- RODA BELAKANG ROBOT -->
  <!-- =================== -->
  <link
    name="rear_left_wheel_link">
    <inertial>
      <origin
        xyz="0 -5.5511E-17 -0.005"
        rpy="0 0 0" />
      <mass value="1" />
      <inertia
        ixx="0.23013"
        ixy="-1.0538E-18"
        ixz="-6.3363E-21"
        iyy="0.23013"
        iyz="8.6783E-22"
        izz="0.42624" />
    </inertial>
    <visual>
      <origin
        xyz="0 0 0"
        rpy="0 0 0" />
      <geometry>
        <mesh
          filename="file://${mesh_path}/lwhell.STL" />
      </geometry>
      <material
        name="">
        <color
          rgba="0.25098 0.25098 0.25098 1" />
      </material>
    </visual>
    <collision>
      <origin
        xyz="0 0 0"
        rpy="0 0 0" />
      <geometry>
        <mesh
          filename="file://${mesh_path}/lwhell.STL" />
      </geometry>
    </collision>
  </link>
  <joint name="rear_left_wheel_joint"
    type="continuous">
    <origin
      xyz="-0.21333 0.43 -0.5817"
      rpy="-1.5708 0 0" />
    <parent
      link="base_link" />
    <child
      link="rear_left_wheel_link" />
    <axis
      xyz="0 0 1" />
    <limit
      effort="10000"
      velocity="200" />
    <dynamics
      damping="0.7"
      friction="0.05"/>
  </joint>
  <link
    name="rear_right_wheel_link">
    <inertial>
      <origin
        xyz="0 -5.55111512312578E-17 0.005"
        rpy="0 0 0" />
      <mass value="1" />
      <inertia
        ixx="0.230133756519099"
        ixy="-1.05387149881349E-18"
        ixz="-6.33625239749178E-21"
        iyy="0.230133756519099"
        iyz="8.67834780809092E-22"
        izz="0.426240533886592" />
    </inertial>
    <visual>
      <origin
        xyz="0 0 0"
        rpy="0 0 0" />
      <geometry>
        <mesh
          filename="file://${mesh_path}/rwheel.STL" />
      </geometry>
      <material
        name="">
        <color
          rgba="0.250980392156863 0.250980392156863 0.250980392156863 1" />
      </material>
    </visual>
    <collision>
      <origin
        xyz="0 0 0"
        rpy="0 0 0" />
      <geometry>
        <mesh
          filename="file://${mesh_path}/rwheel.STL" />
      </geometry>
    </collision>
  </link>
  <joint name="rear_right_wheel_joint"
    type="continuous">
    <origin
      xyz="-0.21333 -0.43 -0.5817"
      rpy="-1.5708 0 0" />
    <parent
      link="base_link" />
    <child
      link="rear_right_wheel_link" />
    <axis
      xyz="0 0 1" />
    <limit
      effort="5000"
      velocity="200" />
    <dynamics
      damping="0.5"
      friction="0.05"/>
  </joint>

  <!-- =================== -->
  <!--        STEER        -->
  <!-- =================== -->
  <link
    name="steer_link">
    <inertial>
      <origin
        xyz="-5.5511E-17 4.1633E-17 -0.047389"
        rpy="0 0 0" />
      <mass value="1" />
      <inertia
        ixx="0.059801"
        ixy="4.0015E-17"
        ixz="5.2334E-17"
        iyy="0.091335"
        iyz="-5.3269E-17"
        izz="0.11925" />
    </inertial>
    <visual>
      <origin
        xyz="0 0 0"
        rpy="0 0 0" />
      <geometry>
        <mesh
          filename="file://${mesh_path}/steer.STL" />
      </geometry>
      <material
        name="">
        <color
          rgba="0.50196 0.50196 0.50196 1" />
      </material>
    </visual>
    <collision>
      <origin
        xyz="0 0 0"
        rpy="0 0 0" />
      <geometry>
        <mesh
          filename="file://${mesh_path}/steer.STL" />
      </geometry>
    </collision>
  </link>
  <joint name="steer_joint"
    type="revolute">
    <origin
      xyz="0.79753 0 -0.3817"
      rpy="0 0 0" />
    <parent
      link="base_link" />
    <child
      link="steer_link" />
    <axis
      xyz="0 0 -1" />
    <limit
      lower="-1.8"
      upper="1.8"
      effort="1000"
      velocity="5" />
    <dynamics
      damping="10.0"
      friction="1.0"/>
  </joint>

  <!-- =================== -->
  <!--   RODA DEPAN ROBOT  -->
  <!-- =================== -->
  <link
    name="front_left_wheel_link">
    <inertial>
      <origin
        xyz="0 -5.5511E-17 -0.005"
        rpy="0 0 0" />
      <mass value="1" />
      <inertia
        ixx="0.14508"
        ixy="7.8789E-20"
        ixz="-1.1766E-20"
        iyy="0.14508"
        iyz="1.1139E-19"
        izz="0.26335" />
    </inertial>
    <visual>
      <origin
        xyz="0 0 0"
        rpy="0 0 0" />
      <geometry>
        <mesh
          filename="file://${mesh_path}/flwheel.STL" />
      </geometry>
      <material
        name="">
        <color
          rgba="0.25098 0.25098 0.25098 1" />
      </material>
    </visual>
    <collision>
      <origin
        xyz="0 0 0"
        rpy="0 0 0" />
      <geometry>
        <mesh
          filename="file://${mesh_path}/flwheel.STL" />
      </geometry>
    </collision>
  </link>
  <joint name="front_left_wheel_joint"
    type="continuous">
    <origin
      xyz="0 0.0875 -0.23"
      rpy="-1.5708 0 0" />
    <parent
      link="steer_link" />
    <child
      link="front_left_wheel_link" />
    <axis
      xyz="0 0 1" />
    <limit
      effort="5000"
      velocity="100" />
    <dynamics
      damping="0.01"
      friction="0.01"/>
  </joint>
  <link
    name="front_right_wheel_link">
    <inertial>
      <origin
        xyz="0 -8.3267E-17 0.005"
        rpy="0 0 0" />
      <mass value="1" />
      <inertia
        ixx="0.14508"
        ixy="-2.0841E-18"
        ixz="3.4593E-18"
        iyy="0.14508"
        iyz="-2.1586E-19"
        izz="0.26335" />
    </inertial>
    <visual>
      <origin
        xyz="0 0 0"
        rpy="0 0 0" />
      <geometry>
        <mesh
          filename="file://${mesh_path}/frwheel.STL" />
      </geometry>
      <material
        name="">
        <color
          rgba="0.25098 0.25098 0.25098 1" />
      </material>
    </visual>
    <collision>
      <origin
        xyz="0 0 0"
        rpy="0 0 0" />
      <geometry>
        <mesh
          filename="file://${mesh_path}/frwheel.STL" />
      </geometry>
    </collision>
  </link>
  <joint name="front_right_wheel_joint"
    type="continuous">
    <origin
      xyz="0 -0.0875 -0.23"
      rpy="-1.5708 0 0" />
    <parent
      link="steer_link" />
    <child
      link="front_right_wheel_link" />
    <axis
      xyz="0 0 1" />
    <limit
      effort="5000"
      velocity="100" />
    <dynamics
      damping="0.01"
      friction="0.01"/>
  </joint>

  <!-- =================== -->
  <!--        TOWING       -->
  <!-- =================== -->
  <link
    name="tow_link">
    <inertial>
      <origin
        xyz="0.11735 -8.1935E-05 -0.30584"
        rpy="0 0 0" />
      <mass value="30" />
      <inertia
        ixx="56.116"
        ixy="-0.74787"
        ixz="7.1158"
        iyy="93.562"
        iyz="0.080093"
        izz="132.22" />
    </inertial>
    <visual>
      <origin
        xyz="0 0 0"
        rpy="0 0 0" />
      <geometry>
        <mesh
          filename="file://${mesh_path}/tow.STL" />
      </geometry>
      <material
        name="">
        <color
          rgba="0.21961 0.44314 1 1" />
      </material>
    </visual>
    <collision>
      <origin
        xyz="0 0 0"
        rpy="0 0 0" />
      <geometry>
        <mesh
          filename="file://${mesh_path}/tow.STL" />
      </geometry>
    </collision>
  </link>
  <joint name="tow_joint"
    type="revolute">
    <origin
      xyz="-0.75497 0 -0.3063"
      rpy="0 0 0" />
    <parent
      link="base_link" />
    <child
      link="tow_link" />
    <axis
      xyz="0 0 1" />
    <limit
      lower="-1.8"
      upper="1.8"
      effort="100"
      velocity="5.0" />
    <dynamics 
      damping="0.5" 
      friction="0.01"/>
  </joint>
  <link
    name="left_tow_steer_link">
    <inertial>
      <origin
        xyz="0 -1.11022302462516E-16 -0.144590259060095"
        rpy="0 0 0" />
      <mass value="1" />
      <inertia
        ixx="0.0200209190929884"
        ixy="7.8284393006792E-19"
        ixz="-2.24430346496892E-18"
        iyy="0.0184123682391828"
        iyz="2.73486480287876E-18"
        izz="0.00344542108379649" />
    </inertial>
    <visual>
      <origin
        xyz="0 0 0"
        rpy="0 0 0" />
      <geometry>
        <mesh
          filename="file://${mesh_path}/ltowsteer.STL" />
      </geometry>
      <material
        name="">
        <color
          rgba="0.792156862745098 0.819607843137255 0.933333333333333 1" />
      </material>
    </visual>
    <collision>
      <origin
        xyz="0 0 0"
        rpy="0 0 0" />
      <geometry>
        <mesh
          filename="file://${mesh_path}/ltowsteer.STL" />
      </geometry>
    </collision>
  </link>
  <joint name="left_tow_steer_joint"
    type="revolute">
    <origin
      xyz="-0.55 0.58 -0.1"
      rpy="0 0 0" />
    <parent
      link="tow_link" />
    <child
      link="left_tow_steer_link" />
    <axis
      xyz="0 0 1" />
    <limit
      lower="-0.8"
      upper="0.8"
      effort="1000"
      velocity="1" />
  </joint>
  <link
    name="left_front_tow_wheel_link">
    <inertial>
      <origin
        xyz="0 0 0"
        rpy="0 0 0" />
      <mass value="1" />
      <inertia
        ixx="0.0292557441107816"
        ixy="2.8472002123967E-36"
        ixz="-1.35465132745924E-19"
        iyy="0.0292557441107816"
        iyz="-9.30574699345486E-35"
        izz="0.0456466663051131" />
    </inertial>
    <visual>
      <origin
        xyz="0 0 0"
        rpy="0 0 0" />
      <geometry>
        <mesh
          filename="file://${mesh_path}/lftowwheel.STL" />
      </geometry>
      <material
        name="">
        <color
          rgba="0.792156862745098 0.819607843137255 0.933333333333333 1" />
      </material>
    </visual>
    <collision>
      <origin
        xyz="0 0 0"
        rpy="0 0 0" />
      <geometry>
        <mesh
          filename="file://${mesh_path}/lftowwheel.STL" />
      </geometry>
    </collision>
  </link>
  <joint name="left_front_tow_wheel_joint"
    type="continuous">
    <origin
      xyz="0 0 -0.265"
      rpy="-1.5708 0 0" />
    <parent
      link="left_tow_steer_link" />
    <child
      link="left_front_tow_wheel_link" />
    <axis
      xyz="0 0 1" />
    <limit
      effort="500"
      velocity="100" />
    <dynamics
      damping="0.1"
      friction="0.1"/>
  </joint>
  <link
    name="right_tow_steer_link">
    <inertial>
      <origin
        xyz="0 0 -0.144590259060095"
        rpy="0 0 0" />
      <mass value="1" />
      <inertia
        ixx="0.0200209190929884"
        ixy="3.81153167456428E-19"
        ixz="8.06532548652751E-18"
        iyy="0.0184123682391828"
        iyz="-2.32762002971695E-18"
        izz="0.00344542108379649" />
    </inertial>
    <visual>
      <origin
        xyz="0 0 0"
        rpy="0 0 0" />
      <geometry>
        <mesh
          filename="file://${mesh_path}/rtowsteer.STL" />
      </geometry>
      <material
        name="">
        <color
          rgba="0.792156862745098 0.819607843137255 0.933333333333333 1" />
      </material>
    </visual>
    <collision>
      <origin
        xyz="0 0 0"
        rpy="0 0 0" />
      <geometry>
        <mesh
          filename="file://${mesh_path}/rtowsteer.STL" />
      </geometry>
    </collision>
  </link>
  <joint name="right_tow_steer_joint"
    type="revolute">
    <origin
      xyz="-0.55 -0.58 -0.1"
      rpy="0 0 0" />
    <parent
      link="tow_link" />
    <child
      link="right_tow_steer_link" />
    <axis
      xyz="0 0 1" />
    <limit
      lower="-0.8"
      upper="0.8"
      effort="1000"
      velocity="1" />
  </joint>
  <link
    name="right_front_tow_wheel_link">
    <inertial>
      <origin
        xyz="2.22044604925031E-16 0 1.11022302462516E-16"
        rpy="0 0 0" />
      <mass value="1" />
      <inertia
        ixx="0.0292557441107816"
        ixy="2.8472002123967E-36"
        ixz="-1.35465132745924E-19"
        iyy="0.0292557441107816"
        iyz="-9.30574699345486E-35"
        izz="0.0456466663051131" />
    </inertial>
    <visual>
      <origin
        xyz="0 0 0"
        rpy="0 0 0" />
      <geometry>
        <mesh
          filename="file://${mesh_path}/rftowwheel.STL" />
      </geometry>
      <material
        name="">
        <color
          rgba="0.792156862745098 0.819607843137255 0.933333333333333 1" />
      </material>
    </visual>
    <collision>
      <origin
        xyz="0 0 0"
        rpy="0 0 0" />
      <geometry>
        <mesh
          filename="file://${mesh_path}/rftowwheel.STL" />
      </geometry>
    </collision>
  </link>
  <joint name="right_front_tow_wheel_joint"
    type="continuous">
    <origin
      xyz="0 0 -0.265"
      rpy="-1.5708 0 0" />
    <parent
      link="right_tow_steer_link" />
    <child
      link="right_front_tow_wheel_link" />
    <axis
      xyz="0 0 1" />
    <limit
      effort="500"
      velocity="100" />
    <dynamics
      damping="0.1"
      friction="0.1"/>
  </joint>
  <link
    name="left_rear_tow_wheel_link">
    <inertial>
      <origin
        xyz="0 0 -1.11022302462516E-16"
        rpy="0 0 0" />
      <mass value="1" />
      <inertia
        ixx="0.0292557441107816"
        ixy="-2.84720021239705E-36"
        ixz="1.58565169114152E-17"
        iyy="0.0292557441107816"
        iyz="9.30574699345486E-35"
        izz="0.0456466663051131" />
    </inertial>
    <visual>
      <origin
        xyz="0 0 0"
        rpy="0 0 0" />
      <geometry>
        <mesh
          filename="file://${mesh_path}/lrtowwheel.STL" />
      </geometry>
      <material
        name="">
        <color
          rgba="0.792156862745098 0.819607843137255 0.933333333333333 1" />
      </material>
    </visual>
    <collision>
      <origin
        xyz="0 0 0"
        rpy="0 0 0" />
      <geometry>
        <mesh
          filename="file://${mesh_path}/lrtowwheel.STL" />
      </geometry>
    </collision>
  </link>
  <joint name="left_rear_tow_wheel_joint"
    type="continuous">
    <origin
      xyz="-2.202 0.58 -0.365"
      rpy="-1.5708 0 0" />
    <parent
      link="tow_link" />
    <child
      link="left_rear_tow_wheel_link" />
    <axis
      xyz="0 0 1" />
    <limit
      effort="500"
      velocity="100" />
    <dynamics
      damping="0.1"
      friction="0.1"/>
  </joint>
  <link
    name="right_rear_tow_wheel_link">
    <inertial>
      <origin
        xyz="0 0 -1.11022302462516E-16"
        rpy="0 0 0" />
      <mass value="1" />
      <inertia
        ixx="0.0292557441107816"
        ixy="-2.84720021239637E-36"
        ixz="-1.34169417456933E-17"
        iyy="0.0292557441107816"
        iyz="9.30574699345486E-35"
        izz="0.0456466663051131" />
    </inertial>
    <visual>
      <origin
        xyz="0 0 0"
        rpy="0 0 0" />
      <geometry>
        <mesh
          filename="file://${mesh_path}/rrtowwheel.STL" />
      </geometry>
      <material
        name="">
        <color
          rgba="0.792156862745098 0.819607843137255 0.933333333333333 1" />
      </material>
    </visual>
    <collision>
      <origin
        xyz="0 0 0"
        rpy="0 0 0" />
      <geometry>
        <mesh
          filename="file://${mesh_path}/rrtowwheel.STL" />
      </geometry>
    </collision>
  </link>
  <joint name="right_rear_tow_wheel_joint"
    type="continuous">
    <origin
      xyz="-2.202 -0.58 -0.365"
      rpy="-1.5708 0 0" />
    <parent
      link="tow_link" />
    <child
      link="right_rear_tow_wheel_link" />
    <axis
      xyz="0 0 1" />
    <limit
      effort="500"
      velocity="100" />
    <dynamics
      damping="0.1"
      friction="0.1"/>
  </joint>
</robot>